Workbook

Sheet Gulshan Dynasty Directory
A1: T | B1: Unit | C1: Status | D1: Owner | E1: Name | F1: Organization Name | G1: Email | H1: Phone 1 | I1: Rented To | J1: Legal Owner
A2: A | B2: 1 | D2: Owner | E2: Anil Anand | F2: HCA GARMENT MACINERY PVT LTD | G2: anilanand@grouphca.com | H2: 919810157990
A3: A | B3: 1 | D3: Owner | E3: Geeta Anand | H3: 919313308701
A4: A | B4: 2 | C4: Staying | D4: Owner | E4: Aastha Todi | H4: 919903355123 | J4: Piyyush Todi
A5: A | B5: 2 | C5: Staying | D5: Owner | E5: Piyyush Todi | F5: Piyyush Todi | G5: piyush.todi80@gmail.com | H5: 919830255123 | J5: Piyyush Todi
A6: A | B6: 101 | C6: Staying | D6: Owner | E6: Ajay Kumar Jain | F6: Bonjour | G6: avnikajain07@gmail.com | H6: 919810144155 | J6: Sweta Jain
A7: A | B7: 101 | C7: Staying | D7: Owner | E7: Saksham | H7: 918527966777 | J7: Sweta Jain
A8: A | B8: 101 | C8: Staying | D8: Owner | E8: Sweta Jain | H8: 919811250059 | J8: Sweta Jain
A9: A | B9: 102 | C9: Staying | D9: Owner | E9: Saksham Jain | J9: Saksham Jain
A10: A | B10: 201 | C10: Staying | D10: Owner | E10: Rohini goyal | H10: 919599004465 | J10: Varun Goyal
A11: A | B11: 201 | C11: Staying | D11: Owner | E11: Varun Goyal | G11: goyal.v81@gmail.com | H11: 919717193449 | J11: Varun Goyal
A12: A | B12: 202 | C12: Staying | D12: Owner | E12: Sanjay Tiku | J12: Sanjay Tiku
A13: A | B13: 301 | C13: Staying | D13: Owner | E13: Neena Rani Agrawal & Prasoon Garg | J13: Neena Rani Agrawal & Prasoon Garg
A14: A | B14: 401 | C14: Staying | D14: Owner | E14: Manu Pathak | H14: 919818113610 | J14: Rajnesh Pathak & Manu Pathak
A15: A | B15: 402 | C15: Rented | D15: Owner | E15: Alok Gupta | F15: Barefoot International | G15: alokgupta62@gmail.com | H15: 917002987662 | I15: Deepa Vohra | J15: Deepika Gupta, Kusum Lata Gupta & Alok Kumar Gupta
A16: A | B16: 402 | C16: Rented | D16: Owner | E16: Deepika Gupta | H16: 919910108722 | I16: Deepa Vohra | J16: Deepika Gupta, Kusum Lata Gupta & Alok Kumar Gupta
A17: A | B17: 501 | C17: Staying | D17: Owner | E17: Jitesh Wahaal | H17: 919999833779 | J17: Aarti Wahal
A18: A | B18: 501 | C18: Staying | D18: Owner | E18: Lata Ravi Wahaal | H18: 919312290624 | J18: Aarti Wahal
A19: A | B19: 502 | C19: Staying | D19: Owner | E19: A Wahaals | H19: 919999181468 | J19: Madhureema Wahal
A20: A | B20: 601 | C20: Staying | D20: Owner | E20: Priya Chugh | F20: Infinity Wealth Advisors | G20: Yogeshchugh785@gmail.com | H20: 919910194315 | J20: Yogesh Chugh
A21: A | B21: 601 | C21: Staying | D21: Owner | E21: Yogesh Chugh | F21: Infinity Wealth Advisors | G21: Yogeshchugh785@gmail.com | H21: 919717983001 | J21: Yogesh Chugh
A22: A | B22: 602 | C22: Staying | D22: Owner | E22: Sanjay Mittal | F22: Maya Industries | G22: chiragmittal13@gmail.com | H22: 919811079274 | J22: Mr. Sanjay Mittal
A23: A | B23: 702 | C23: Staying | D23: Owner | E23: Ayush Goel | G23: goelay@gmail.com | H23: 919999287859 | J23: Ayush Goel & Kumud Goel
A24: A | B24: 702 | C24: Staying | D24: Owner | E24: Kritika Goel | H24: 919999452987 | J24: Ayush Goel & Kumud Goel
A25: A | B25: 702 | C25: Staying | D25: Owner | E25: Sk Goel | H25: 919350545285 | J25: Ayush Goel & Kumud Goel
A26: A | B26: 801 | C26: Staying | D26: Owner | E26: Manjula Pandey | F26: P N D Global Logistics | G26: pankaj.mishra@pdgl.in | H26: 919717591231 | J26: Manjula Pandey
A27: A | B27: 801 | C27: Staying | D27: Owner | E27: Pankaj Mishra | H27: 919999960068 | J27: Manjula Pandey
A28: A | B28: 802 | C28: Staying | D28: Owner | E28: Lalit Kakrania | H28: 919873744055 | J28: Lalit Kakrania
A29: A | B29: 902 | C29: Staying | D29: Owner | E29: Rupal Gupta | J29: Rupal Gupta
A30: A | B30: 1001 | C30: Staying | D30: Owner | E30: Seema Jain | J30: Seema Jain
A31: A | B31: 1002 | C31: Staying | D31: Owner | E31: Brajesh Kumar | J31: Brajesh Kumar
A32: A | B32: 1101 | C32: Staying | D32: Owner | E32: Preeti Jain | H32: 919971444918 | J32: Ravinder Jain
A33: A | B33: 1101 | C33: Staying | D33: Owner | E33: Ravinder Jain | F33: Shalvi Enterprises | G33: ravinderjn44@gmail.com | H33: 919810173072 | J33: Ravinder Jain
A34: A | B34: 1102 | C34: Rented | D34: Owner | E34: Rajdeep Singh | I34: Anurag Bhati | J34: Rajdeep Singh
A35: A | B35: 1102 | C35: Rented | D35: Tenant | E35: Anurag Bhati | H35: 919971330700 | I35: Anurag Bhati | J35: Rajdeep Singh
A36: A | B36: 1102 | C36: Rented | D36: Tenant | E36: Nitika Pawar | H36: 919333939993 | I36: Anurag Bhati | J36: Rajdeep Singh
A37: A | B37: 1201 | C37: Staying | D37: Owner | E37: Lav jain | F37: Geburt plast pvt ltd | G37: lavj1712@gmail.com | H37: 919711142505 | J37: Priyanka Rajput & Abhishek Arora
A38: A | B38: 1202 | C38: Staying | D38: Owner | E38: Nishi Goel | H38: 919311145222 | J38: Surender Kumar Goel
A39: A | B39: 1202 | C39: Staying | D39: Owner | E39: Surender Kumar Goel | F39: Kishan Lal Surender Kumar | G39: arvind273@gmail.com | H39: 919810101222 | J39: Surender Kumar Goel
A40: A | B40: 1401 | C40: Staying | D40: Owner | E40: Ritika Kohli | H40: 919999700539 | J40: Rohit Kohli & Seema Kohli
...

Sheet Chetan LIst
B1: Tower | C1: Unit | D1: Owner | E1: Tenant
A2: =_xlfn.CONCAT(B2:C2) -> A2 | B2: A | C2: 2 | D2: Piyyush Todi | F2: =VLOOKUP(A2,'Gulshan Dynasty Directory'!A:E,6,0) -> #N/A | G2: =F2=D2 -> #N/A
A3: =_xlfn.CONCAT(B3:C3) -> A101 | B3: A | C3: 101 | D3: Sweta Jain | F3: =VLOOKUP(A3,'Gulshan Dynasty Directory'!A:E,6,0) -> #N/A | G3: =F3=D3 -> #N/A
A4: =_xlfn.CONCAT(B4:C4) -> A102 | B4: A | C4: 102 | D4: Saksham Jain | F4: =VLOOKUP(A4,'Gulshan Dynasty Directory'!A:E,6,0) -> #N/A | G4: =F4=D4 -> #N/A
A5: =_xlfn.CONCAT(B5:C5) -> A201 | B5: A | C5: 201 | D5: Varun Goyal | F5: =VLOOKUP(A5,'Gulshan Dynasty Directory'!A:E,6,0) -> #N/A | G5: =F5=D5 -> #N/A
A6: =_xlfn.CONCAT(B6:C6) -> A202 | B6: A | C6: 202 | D6: Sanjay Tiku | F6: =VLOOKUP(A6,'Gulshan Dynasty Directory'!A:E,6,0) -> #N/A | G6: =F6=D6 -> #N/A
A7: =_xlfn.CONCAT(B7:C7) -> A301 | B7: A | C7: 301 | D7: Neena Rani Agrawal & Prasoon Garg | F7: =VLOOKUP(A7,'Gulshan Dynasty Directory'!A:E,6,0) -> #N/A | G7: =F7=D7 -> #N/A
A8: =_xlfn.CONCAT(B8:C8) -> A401 | B8: A | C8: 401 | D8: Rajnesh Pathak & Manu Pathak | F8: =VLOOKUP(A8,'Gulshan Dynasty Directory'!A:E,6,0) -> #N/A | G8: =F8=D8 -> #N/A
A9: =_xlfn.CONCAT(B9:C9) -> A402 | B9: A | C9: 402 | D9: Deepika Gupta, Kusum Lata Gupta & Alok Kumar Gupta | E9: Deepa Vohra (Tenant) | F9: =VLOOKUP(A9,'Gulshan Dynasty Directory'!A:E,6,0) -> #N/A | G9: =F9=D9 -> #N/A
A10: =_xlfn.CONCAT(B10:C10) -> A501 | B10: A | C10: 501 | D10: Aarti Wahal | F10: =VLOOKUP(A10,'Gulshan Dynasty Directory'!A:E,6,0) -> #N/A | G10: =F10=D10 -> #N/A
A11: =_xlfn.CONCAT(B11:C11) -> A502 | B11: A | C11: 502 | D11: Madhureema Wahal | F11: =VLOOKUP(A11,'Gulshan Dynasty Directory'!A:E,6,0) -> #N/A | G11: =F11=D11 -> #N/A
A12: =_xlfn.CONCAT(B12:C12) -> A601 | B12: A | C12: 601 | D12: Yogesh Chugh | F12: =VLOOKUP(A12,'Gulshan Dynasty Directory'!A:E,6,0) -> #N/A | G12: =F12=D12 -> #N/A
A13: =_xlfn.CONCAT(B13:C13) -> A602 | B13: A | C13: 602 | D13: Mr. Sanjay Mittal | F13: =VLOOKUP(A13,'Gulshan Dynasty Directory'!A:E,6,0) -> #N/A | G13: =F13=D13 -> #N/A
A14: =_xlfn.CONCAT(B14:C14) -> A702 | B14: A | C14: 702 | D14: Ayush Goel & Kumud Goel | F14: =VLOOKUP(A14,'Gulshan Dynasty Directory'!A:E,6,0) -> #N/A | G14: =F14=D14 -> #N/A
A15: =_xlfn.CONCAT(B15:C15) -> A801 | B15: A | C15: 801 | D15: Manjula Pandey | F15: =VLOOKUP(A15,'Gulshan Dynasty Directory'!A:E,6,0) -> #N/A | G15: =F15=D15 -> #N/A
A16: =_xlfn.CONCAT(B16:C16) -> A802 | B16: A | C16: 802 | D16: Lalit Kakrania | F16: =VLOOKUP(A16,'Gulshan Dynasty Directory'!A:E,6,0) -> #N/A | G16: =F16=D16 -> #N/A
A17: =_xlfn.CONCAT(B17:C17) -> A902 | B17: A | C17: 902 | D17: Rupal Gupta | F17: =VLOOKUP(A17,'Gulshan Dynasty Directory'!A:E,6,0) -> #N/A | G17: =F17=D17 -> #N/A
A18: =_xlfn.CONCAT(B18:C18) -> A1001 | B18: A | C18: 1001 | D18: Seema Jain | F18: =VLOOKUP(A18,'Gulshan Dynasty Directory'!A:E,6,0) -> #N/A | G18: =F18=D18 -> #N/A
A19: =_xlfn.CONCAT(B19:C19) -> A1002 | B19: A | C19: 1002 | D19: Brajesh Kumar | F19: =VLOOKUP(A19,'Gulshan Dynasty Directory'!A:E,6,0) -> #N/A | G19: =F19=D19 -> #N/A
A20: =_xlfn.CONCAT(B20:C20) -> A1101 | B20: A | C20: 1101 | D20: Ravinder Jain | F20: =VLOOKUP(A20,'Gulshan Dynasty Directory'!A:E,6,0) -> #N/A | G20: =F20=D20 -> #N/A
A21: =_xlfn.CONCAT(B21:C21) -> A1102 | B21: A | C21: 1102 | D21: Rajdeep Singh | E21: Anurag Bhati (Tenant) | F21: =VLOOKUP(A21,'Gulshan Dynasty Directory'!A:E,6,0) -> #N/A | G21: =F21=D21 -> #N/A
A22: =_xlfn.CONCAT(B22:C22) -> A1201 | B22: A | C22: 1201 | D22: Priyanka Rajput & Abhishek Arora | F22: =VLOOKUP(A22,'Gulshan Dynasty Directory'!A:E,6,0) -> #N/A | G22: =F22=D22 -> #N/A
A23: =_xlfn.CONCAT(B23:C23) -> A1202 | B23: A | C23: 1202 | D23: Surender Kumar Goel | F23: =VLOOKUP(A23,'Gulshan Dynasty Directory'!A:E,6,0) -> #N/A | G23: =F23=D23 -> #N/A
A24: =_xlfn.CONCAT(B24:C24) -> A1401 | B24: A | C24: 1401 | D24: Rohit Kohli & Seema Kohli | F24: =VLOOKUP(A24,'Gulshan Dynasty Directory'!A:E,6,0) -> #N/A | G24: =F24=D24 -> #N/A
A25: =_xlfn.CONCAT(B25:C25) -> A1402 | B25: A | C25: 1402 | D25: Rahul Srivastava | F25: =VLOOKUP(A25,'Gulshan Dynasty Directory'!A:E,6,0) -> #N/A | G25: =F25=D25 -> #N/A
A26: =_xlfn.CONCAT(B26:C26) -> A1501 | B26: A | C26: 1501 | D26: Subhash Jain & Arunima Jain | F26: =VLOOKUP(A26,'Gulshan Dynasty Directory'!A:E,6,0) -> #N/A | G26: =F26=D26 -> #N/A
A27: =_xlfn.CONCAT(B27:C27) -> A1502 | B27: A | C27: 1502 | D27: Amit Mehta | F27: =VLOOKUP(A27,'Gulshan Dynasty Directory'!A:E,6,0) -> #N/A | G27: =F27=D27 -> #N/A
A28: =_xlfn.CONCAT(B28:C28) -> A1601 | B28: A | C28: 1601 | D28: Nikhil Kumar Tyagi | F28: =VLOOKUP(A28,'Gulshan Dynasty Directory'!A:E,6,0) -> #N/A | G28: =F28=D28 -> #N/A
A29: =_xlfn.CONCAT(B29:C29) -> A1602 | B29: A | C29: 1602 | D29: Arun Khetarpal, Kamini Khetarpal & Ramesh Kumar Khetarpal | F29: =VLOOKUP(A29,'Gulshan Dynasty Directory'!A:E,6,0) -> #N/A | G29: =F29=D29 -> #N/A
A30: =_xlfn.CONCAT(B30:C30) -> A1701 | B30: A | C30: 1701 | D30: Sneha Vardhan & Aman Varma | F30: =VLOOKUP(A30,'Gulshan Dynasty Directory'!A:E,6,0) -> #N/A | G30: =F30=D30 -> #N/A
A31: =_xlfn.CONCAT(B31:C31) -> A1702 | B31: A | C31: 1702 | D31: Mukesh Yadav & Anita Yadav | F31: =VLOOKUP(A31,'Gulshan Dynasty Directory'!A:E,6,0) -> #N/A | G31: =F31=D31 -> #N/A
A32: =_xlfn.CONCAT(B32:C32) -> A1802 | B32: A | C32: 1802 | D32: Anita Dhawan & Vikas Dhawan | F32: =VLOOKUP(A32,'Gulshan Dynasty Directory'!A:E,6,0) -> #N/A | G32: =F32=D32 -> #N/A
A33: =_xlfn.CONCAT(B33:C33) -> A2001 | B33: A | C33: 2001 | D33: Aaxis Nano Technologies Pvt Ltd | F33: =VLOOKUP(A33,'Gulshan Dynasty Directory'!A:E,6,0) -> #N/A | G33: =F33=D33 -> #N/A
... A59: =_xlfn.CONCAT(B59:C59) -> B2 | B59: B | C59: 2 | D59: Payal Yadav / Akshar Yadav | F59: =VLOOKUP(A59,'Gulshan Dynasty Directory'!A:E,6,0) -> #N/A | G59: =F59=D59 -> #N/A
A60: =_xlfn.CONCAT(B60:C60) -> B101 | B60: B | C60: 101 | D60: Shakuntala Devi | E60: Gurveer & Puneet Kaur (Tenant) | F60: =VLOOKUP(A60,'Gulshan Dynasty Directory'!A:E,6,0) -> #N/A | G60: =F60=D60 -> #N/A
A61: =_xlfn.CONCAT(B61:C61) -> B102 | B61: B | C61: 102 | D61: Manoj Jhalani & Honey Jhalani | E61: Mohit Goel (Tenant) | F61: =VLOOKUP(A61,'Gulshan Dynasty Directory'!A:E,6,0) -> #N/A | G61: =F61=D61 -> #N/A
A62: =_xlfn.CONCAT(B62:C62) -> B201 | B62: B | C62: 201 | D62: Aarushi Vikram | F62: =VLOOKUP(A62,'Gulshan Dynasty Directory'!A:E,6,0) -> #N/A | G62: =F62=D62 -> #N/A
A63: =_xlfn.CONCAT(B63:C63) -> B202 | B63: B | C63: 202 | D63: Geetika Agarwal & Nitin Kumar Gupta | F63: =VLOOKUP(A63,'Gulshan Dynasty Directory'!A:E,6,0) -> #N/A | G63: =F63=D63 -> #N/A
A64: =_xlfn.CONCAT(B64:C64) -> B301 | B64: B | C64: 301 | D64: Beena Lawania | F64: =VLOOKUP(A64,'Gulshan Dynasty Directory'!A:E,6,0) -> #N/A | G64: =F64=D64 -> #N/A
A65: =_xlfn.CONCAT(B65:C65) -> B302 | B65: B | C65: 302 | D65: Harish Kumar Goyal & Vanita Goyal | F65: =VLOOKUP(A65,'Gulshan Dynasty Directory'!A:E,6,0) -> #N/A | G65: =F65=D65 -> #N/A
...

Sheet Sheet1
A2: Status | B2: (All)
A4: Count of Name | D4: Owner
A5: T | B5: Unit | C5: Name | D5: Owner | E5: Tenant
A6: A | B6: 1 | D6: 2
B7: 2 | D7: 2
B8: 101 | D8: 3
B9: 201 | D9: 2
B10: 401 | D10: 1
B11: 402 | D11: 2
B12: 501 | D12: 2
B13: 502 | D13: 1
B14: 601 | D14: 2
B15: 602 | D15: 1
B16: 702 | D16: 3
B17: 801 | D17: 2
B18: 802 | D18: 1
B19: 1101 | D19: 2
B20: 1102 | D20: 1 | E20: 2
B21: 1201 | D21: 1
B22: 1202 | D22: 2
B23: 1401 | D23: 2
B24: 1402 | D24: 1
B25: 1501 | D25: 3
B26: 1601 | D26: 2
B27: 1602 | D27: 3
B28: 1701 | D28: 2
B29: 1702 | D29: 2
B30: 1802 | D30: 1
B31: 2101 | D31: 3
B32: 2201 | D32: 2
... B50: 3202 | D50: 2
A51: B | B51: 1 | D51: 1
B52: 102 | D52: 1
B53: 202 | D53: 3
B54: 302 | D54: 2
B55: 501 | D55: 2
B56: 502 | D56: 1
B57: 601 | D57: 2
B58: 602 | D58: 1 | E58: 2
B59: 701 | D59: 2
...
